Traceback (most recent call last):
  File "/app/app.py", line 10, in <module>
    from config.crew import scenario_crew
  File "/app/config/crew.py", line 2, in <module>
    from config.agents import (
  File "/app/config/agents.py", line 9, in <module>
    llm = ChatGoogleGenerativeAI(model="gemini-1.5-flash",
          ^^^^^^^^^^^^^^^^^^^^^^^^^^^^^^^^^^^^^^^^^^^^^^^^
  File "/home/jules/.pyenv/versions/3.12.11/lib/python3.12/site-packages/langchain_google_genai/chat_models.py", line 1345, in __init__
    super().__init__(**kwargs)
  File "/home/jules/.pyenv/versions/3.12.11/lib/python3.12/site-packages/langchain_core/load/serializable.py", line 130, in __init__
    super().__init__(*args, **kwargs)
  File "/home/jules/.pyenv/versions/3.12.11/lib/python3.12/site-packages/pydantic/main.py", line 253, in __init__
    validated_self = self.__pydantic_validator__.validate_python(data, self_instance=self)
                     ^^^^^^^^^^^^^^^^^^^^^^^^^^^^^^^^^^^^^^^^^^^^^^^^^^^^^^^^^^^^^^^^^^^^^
  File "/home/jules/.pyenv/versions/3.12.11/lib/python3.12/site-packages/langchain_google_genai/chat_models.py", line 1404, in validate_environment
    self.client = genaix.build_generative_service(
                  ^^^^^^^^^^^^^^^^^^^^^^^^^^^^^^^^
  File "/home/jules/.pyenv/versions/3.12.11/lib/python3.12/site-packages/langchain_google_genai/_genai_extension.py", line 276, in build_generative_service
    return v1betaGenerativeServiceClient(**config)
           ^^^^^^^^^^^^^^^^^^^^^^^^^^^^^^^^^^^^^^^
  File "/home/jules/.pyenv/versions/3.12.11/lib/python3.12/site-packages/google/ai/generativelanguage_v1beta/services/generative_service/client.py", line 697, in __init__
    self._transport = transport_init(
                      ^^^^^^^^^^^^^^^
  File "/home/jules/.pyenv/versions/3.12.11/lib/python3.12/site-packages/google/ai/generativelanguage_v1beta/services/generative_service/transports/grpc.py", line 234, in __init__
    super().__init__(
  File "/home/jules/.pyenv/versions/3.12.11/lib/python3.12/site-packages/google/ai/generativelanguage_v1beta/services/generative_service/transports/base.py", line 100, in __init__
    credentials, _ = google.auth.default(
                     ^^^^^^^^^^^^^^^^^^^^
  File "/home/jules/.pyenv/versions/3.12.11/lib/python3.12/site-packages/google/auth/_default.py", line 685, in default
    raise exceptions.DefaultCredentialsError(_CLOUD_SDK_MISSING_CREDENTIALS)
google.auth.exceptions.DefaultCredentialsError: Your default credentials were not found. To set up Application Default Credentials, see https://cloud.google.com/docs/authentication/external/set-up-adc for more information.
